Workbook

Sheet Sheet2
A3: Row Labels
A4: 1
A5: 2
A6: 50000
A7: 50000 investement
A8: Details Share once again
A9: Month End
A10: Rejected
A11: RejectedR6
A12: vadodra Hr no / 3 NR
A13: Will Come
A14: Will decide and Call
A15: Will Take Decious / Rejected
A16: will take time
A17: / fever once he ias ok
A18: / Pospond
... A215: YashPal no Given / Will Take time
A216: 46028
A217: (blank)
A218: Grand Total

Sheet Sheet3
A3: Row Labels
A4: Deal
A5: Deal
A6: Follow up
A7: Rejected
A8: Rejected
A9: Ringing
A10: (blank)
A11: Grand Total

Sheet Sheet13
A3: Row Labels
A4: Assam | B4: East
A5: Bihar | B5: East
A6: Bihar
A7: Chattisgarh | B7: Central
A8: Delhi | B8: North
A9: Goa | B9: West
A10: Gujarat | B10: West
A11: Gujarat
A12: Haryana | B12: North
A13: haryana
A14: jharkhand | B14: East
A15: Madhya Pradesh | B15: Central
A16: Maharashtra | B16: West
A17: Manipur | B17: East
A18: Meghalaya | B18: East
A19: Odisha | B19: East
A20: Punjab | B20: North
A21: Punjab
A22: Rajasthan | B22: West
A23: Uttar Pradesh | B23: North
A24: Uttar Pradesh
A25: Uttrakhand | B25: North
A26: West Bengal | B26: East
A27: (blank)
A28: Grand Total

Sheet Sheet14
A1: Assam | B1: East
A2: Bihar | B2: East
A3: Chattisgarh | B3: Central
A4: Delhi | B4: North
A5: Goa | B5: West
A6: Gujarat | B6: West
A7: Haryana | B7: North
A8: jharkhand | B8: East
A9: Madhya Pradesh | B9: Central
A10: Maharashtra | B10: West
A11: Manipur | B11: East
A12: Meghalaya | B12: East
... A18: West Bengal | B18: East

Sheet Dashboard
A1: Franchise Sales Performance Dashboard
A3: Lead Conversion • Revenue • Sales Performance Analytics
A5: 📞Total Leads | E5: Conversion Rate % | I5: Revenue Generated
A6: =KPI_Databse!B1 -> 1778 | E6: =KPI_Databse!B3 -> 0.025309336 | I6: =KPI_Databse!B4 -> 6198000
A11: Pipeline Value | E11: Lost Opportunity | I11: Avg Days To Closure
A12: =KPI_Databse!B5 -> 69576000 | E12: =KPI_Databse!B6 -> 119264000 | I12: =KPI_Databse!B7 -> 13

Sheet Cleaned_CRM_Data
A1: Lead ID | B1: Date | C1: Campaign | D1: Clean_Campaign | E1: Name | F1: city | G1: State | H1: Remark | I1: Franchise Package Amount | J1: investment Amount | K1: Clean_Remark | L1: Standard Status | M1: Closing Date | N1: Days To Closure | O1: Pacakge Category | P1: Lead Month | Q1: Lead Quarter | R1: Zone
A2: ="EOS"&TEXT(ROW()-1,"0000") -> EOS0001 | B2: 45817 | C2: FB | D2: =TRIM(CLEAN(SUBSTITUTE(C2,CHAR(160),""))) -> FB | E2: Rathod Kuldipsinh | F2: Kodinar | G2: Gujarat | H2: Rejected | I2: 130000 | J2: 107000 | K2: =TRIM(Cleaned_CRM_Data!H2) -> Rejected | L2: =IFERROR(VLOOKUP(K2, Status_Mapping!A:B, 2,), "Not Found") -> Rejected | N2: =IF(M2="","",M2-B2) | O2: =IF(OR(I2=108000,I2=130000),"Starter",IF(I2=177000,"Growth","Premium")) -> Starter | P2: =TEXT(B2, "mmmm") -> June | Q2: ="Q"&ROUNDUP(MONTH(B2)/3,0) -> Q2 | R2: =IFERROR(VLOOKUP(TRIM(CLEAN(G2)),Sheet14!$A$2:$B$19,2,FALSE),"Not Mapped") -> West
A3: ="EOS"&TEXT(ROW()-1,"0000") -> EOS0002 | B3: 45817 | C3: FB | D3: =TRIM(CLEAN(SUBSTITUTE(C3,CHAR(160),""))) -> FB | E3: Kiran Lashkari | F3: Bhavnagar | G3: Gujarat | H3: Rejected | I3: 108000 | J3: 107001 | K3: =TRIM(Cleaned_CRM_Data!H3) -> Rejected | L3: =IFERROR(VLOOKUP(K3, Status_Mapping!A:B, 2,), "Not Found") -> Rejected | N3: =IF(M3="","",M3-B3) | O3: =IF(OR(I3=108000,I3=130000),"Starter",IF(I3=177000,"Growth","Premium")) -> Starter | P3: =TEXT(B3, "mmmm") -> June | Q3: ="Q"&ROUNDUP(MONTH(B3)/3,0) -> Q2 | R3: =IFERROR(VLOOKUP(TRIM(CLEAN(G3)),Sheet14!$A$2:$B$19,2,FALSE),"Not Mapped") -> West
A4: ="EOS"&TEXT(ROW()-1,"0000") -> EOS0003 | B4: 45817 | C4: FB | D4: =TRIM(CLEAN(SUBSTITUTE(C4,CHAR(160),""))) -> FB | E4: Abhay Naik | F4: Bardoli | G4: Gujarat | H4: Rejected | I4: 108000 | J4: 107002 | K4: =TRIM(Cleaned_CRM_Data!H4) -> Rejected | L4: =IFERROR(VLOOKUP(K4, Status_Mapping!A:B, 2,), "Not Found") -> Rejected | N4: =IF(M4="","",M4-B4) | O4: =IF(OR(I4=108000,I4=130000),"Starter",IF(I4=177000,"Growth","Premium")) -> Starter | P4: =TEXT(B4, "mmmm") -> June | Q4: ="Q"&ROUNDUP(MONTH(B4)/3,0) -> Q2 | R4: =IFERROR(VLOOKUP(TRIM(CLEAN(G4)),Sheet14!$A$2:$B$19,2,FALSE),"Not Mapped") -> West
A5: ="EOS"&TEXT(ROW()-1,"0000") -> EOS0004 | B5: 45817 | C5: FB | D5: =TRIM(CLEAN(SUBSTITUTE(C5,CHAR(160),""))) -> FB | E5: Kunalpatel | F5: Ahmedabad | G5: Gujarat | H5: Rejected | I5: 177000 | J5: 107003 | K5: =TRIM(Cleaned_CRM_Data!H5) -> Rejected | L5: =IFERROR(VLOOKUP(K5, Status_Mapping!A:B, 2,), "Not Found") -> Rejected | N5: =IF(M5="","",M5-B5) | O5: =IF(OR(I5=108000,I5=130000),"Starter",IF(I5=177000,"Growth","Premium")) -> Growth | P5: =TEXT(B5, "mmmm") -> June | Q5: ="Q"&ROUNDUP(MONTH(B5)/3,0) -> Q2 | R5: =IFERROR(VLOOKUP(TRIM(CLEAN(G5)),Sheet14!$A$2:$B$19,2,FALSE),"Not Mapped") -> West
A6: ="EOS"&TEXT(ROW()-1,"0000") -> EOS0005 | B6: 45817 | C6: FB | D6: =TRIM(CLEAN(SUBSTITUTE(C6,CHAR(160),""))) -> FB | E6: Kartik Kesarwani | F6: Allahabad | G6: Uttar Pradesh | H6: Rejected | I6: 177000 | J6: 107004 | K6: =TRIM(Cleaned_CRM_Data!H6) -> Rejected | L6: =IFERROR(VLOOKUP(K6, Status_Mapping!A:B, 2,), "Not Found") -> Rejected | N6: =IF(M6="","",M6-B6) | O6: =IF(OR(I6=108000,I6=130000),"Starter",IF(I6=177000,"Growth","Premium")) -> Growth | P6: =TEXT(B6, "mmmm") -> June | Q6: ="Q"&ROUNDUP(MONTH(B6)/3,0) -> Q2 | R6: =IFERROR(VLOOKUP(TRIM(CLEAN(G6)),Sheet14!$A$2:$B$19,2,FALSE),"Not Mapped") -> North
A7: ="EOS"&TEXT(ROW()-1,"0000") -> EOS0006 | B7: 45817 | C7: FB | D7: =TRIM(CLEAN(SUBSTITUTE(C7,CHAR(160),""))) -> FB | E7: Golu_Dwivedi | F7: Gonda | G7: Uttar Pradesh | H7: Rejected | I7: 308000 | J7: 107005 | K7: =TRIM(Cleaned_CRM_Data!H7) -> Rejected | L7: =IFERROR(VLOOKUP(K7, Status_Mapping!A:B, 2,), "Not Found") -> Rejected | N7: =IF(M7="","",M7-B7) | O7: =IF(OR(I7=108000,I7=130000),"Starter",IF(I7=177000,"Growth","Premium")) -> Premium | P7: =TEXT(B7, "mmmm") -> June | Q7: ="Q"&ROUNDUP(MONTH(B7)/3,0) -> Q2 | R7: =IFERROR(VLOOKUP(TRIM(CLEAN(G7)),Sheet14!$A$2:$B$19,2,FALSE),"Not Mapped") -> North
A8: ="EOS"&TEXT(ROW()-1,"0000") -> EOS0007 | B8: 45817 | C8: FB | D8: =TRIM(CLEAN(SUBSTITUTE(C8,CHAR(160),""))) -> FB | E8: સહજાનંદી સિંહ ધુ્વિક પટેલ | F8: Padra | G8: Gujarat | H8: Rejected | I8: 108000 | J8: 107006 | K8: =TRIM(Cleaned_CRM_Data!H8) -> Rejected | L8: =IFERROR(VLOOKUP(K8, Status_Mapping!A:B, 2,), "Not Found") -> Rejected | N8: =IF(M8="","",M8-B8) | O8: =IF(OR(I8=108000,I8=130000),"Starter",IF(I8=177000,"Growth","Premium")) -> Starter | P8: =TEXT(B8, "mmmm") -> June | Q8: ="Q"&ROUNDUP(MONTH(B8)/3,0) -> Q2 | R8: =IFERROR(VLOOKUP(TRIM(CLEAN(G8)),Sheet14!$A$2:$B$19,2,FALSE),"Not Mapped") -> West
A9: ="EOS"&TEXT(ROW()-1,"0000") -> EOS0008 | B9: 45817 | C9: FB | D9: =TRIM(CLEAN(SUBSTITUTE(C9,CHAR(160),""))) -> FB | E9: Het Thacker | F9: Bhuj | G9: Gujarat | H9: Rejected | I9: 130000 | J9: 107007 | K9: =TRIM(Cleaned_CRM_Data!H9) -> Rejected | L9: =IFERROR(VLOOKUP(K9, Status_Mapping!A:B, 2,), "Not Found") -> Rejected | N9: =IF(M9="","",M9-B9) | O9: =IF(OR(I9=108000,I9=130000),"Starter",IF(I9=177000,"Growth","Premium")) -> Starter | P9: =TEXT(B9, "mmmm") -> June | Q9: ="Q"&ROUNDUP(MONTH(B9)/3,0) -> Q2 | R9: =IFERROR(VLOOKUP(TRIM(CLEAN(G9)),Sheet14!$A$2:$B$19,2,FALSE),"Not Mapped") -> West
A10: ="EOS"&TEXT(ROW()-1,"0000") -> EOS0009 | B10: 45817 | C10: FB | D10: =TRIM(CLEAN(SUBSTITUTE(C10,CHAR(160),""))) -> FB | E10: Chintan Patel | F10: Ahmedabad | G10: Gujarat | H10: Rejected | I10: 108000 | J10: 107008 | K10: =TRIM(Cleaned_CRM_Data!H10) -> Rejected | L10: =IFERROR(VLOOKUP(K10, Status_Mapping!A:B, 2,), "Not Found") -> Rejected | N10: =IF(M10="","",M10-B10) | O10: =IF(OR(I10=108000,I10=130000),"Starter",IF(I10=177000,"Growth","Premium")) -> Starter | P10: =TEXT(B10, "mmmm") -> June | Q10: ="Q"&ROUNDUP(MONTH(B10)/3,0) -> Q2 | R10: =IFERROR(VLOOKUP(TRIM(CLEAN(G10)),Sheet14!$A$2:$B$19,2,FALSE),"Not Mapped") -> West
A11: ="EOS"&TEXT(ROW()-1,"0000") -> EOS0010 | B11: 45817 | C11: FB | D11: =TRIM(CLEAN(SUBSTITUTE(C11,CHAR(160),""))) -> FB | E11: Rohit | F11: Baroda | G11: Gujarat | H11: Rejected | I11: 130000 | J11: 107009 | K11: =TRIM(Cleaned_CRM_Data!H11) -> Rejected | L11: =IFERROR(VLOOKUP(K11, Status_Mapping!A:B, 2,), "Not Found") -> Rejected | N11: =IF(M11="","",M11-B11) | O11: =IF(OR(I11=108000,I11=130000),"Starter",IF(I11=177000,"Growth","Premium")) -> Starter | P11: =TEXT(B11, "mmmm") -> June | Q11: ="Q"&ROUNDUP(MONTH(B11)/3,0) -> Q2 | R11: =IFERROR(VLOOKUP(TRIM(CLEAN(G11)),Sheet14!$A$2:$B$19,2,FALSE),"Not Mapped") -> West
A12: ="EOS"&TEXT(ROW()-1,"0000") -> EOS0011 | B12: 45817 | C12: FB | D12: =TRIM(CLEAN(SUBSTITUTE(C12,CHAR(160),""))) -> FB | E12: Balvantsinh Zala | F12: Somnath | G12: Gujarat | H12: Rejected | I12: 108000 | J12: 107010 | K12: =TRIM(Cleaned_CRM_Data!H12) -> Rejected | L12: =IFERROR(VLOOKUP(K12, Status_Mapping!A:B, 2,), "Not Found") -> Rejected | N12: =IF(M12="","",M12-B12) | O12: =IF(OR(I12=108000,I12=130000),"Starter",IF(I12=177000,"Growth","Premium")) -> Starter | P12: =TEXT(B12, "mmmm") -> June | Q12: ="Q"&ROUNDUP(MONTH(B12)/3,0) -> Q2 | R12: =IFERROR(VLOOKUP(TRIM(CLEAN(G12)),Sheet14!$A$2:$B$19,2,FALSE),"Not Mapped") -> West
A13: ="EOS"&TEXT(ROW()-1,"0000") -> EOS0012 | B13: 45817 | C13: FB | D13: =TRIM(CLEAN(SUBSTITUTE(C13,CHAR(160),""))) -> FB | E13: Rohit Yadav | F13: Kota | G13: Rajasthan | H13: Rejected | I13: 130000 | J13: 107011 | K13: =TRIM(Cleaned_CRM_Data!H13) -> Rejected | L13: =IFERROR(VLOOKUP(K13, Status_Mapping!A:B, 2,), "Not Found") -> Rejected | N13: =IF(M13="","",M13-B13) | O13: =IF(OR(I13=108000,I13=130000),"Starter",IF(I13=177000,"Growth","Premium")) -> Starter | P13: =TEXT(B13, "mmmm") -> June | Q13: ="Q"&ROUNDUP(MONTH(B13)/3,0) -> Q2 | R13: =IFERROR(VLOOKUP(TRIM(CLEAN(G13)),Sheet14!$A$2:$B$19,2,FALSE),"Not Mapped") -> West
... A18: ="EOS"&TEXT(ROW()-1,"0000") -> EOS0017 | B18: 45817 | C18: FB | D18: =TRIM(CLEAN(SUBSTITUTE(C18,CHAR(160),""))) -> FB | E18: Kunal Dafda | F18: Rajkot | G18: Gujarat | H18: Rejected | I18: 108000 | J18: 107016 | K18: =TRIM(Cleaned_CRM_Data!H18) -> Rejected | L18: =IFERROR(VLOOKUP(K18, Status_Mapping!A:B, 2,), "Not Found") -> Rejected | N18: =IF(M18="","",M18-B18) | O18: =IF(OR(I18=108000,I18=130000),"Starter",IF(I18=177000,"Growth","Premium")) -> Starter | P18: =TEXT(B18, "mmmm") -> June | Q18: ="Q"&ROUNDUP(MONTH(B18)/3,0) -> Q2 | R18: =IFERROR(VLOOKUP(TRIM(CLEAN(G18)),Sheet14!$A$2:$B$19,2,FALSE),"Not Mapped") -> West
A19: ="EOS"&TEXT(ROW()-1,"0000") -> EOS0018 | B19: 45817 | C19: FB | D19: =TRIM(CLEAN(SUBSTITUTE(C19,CHAR(160),""))) -> FB | E19: Jignesh Parekh | F19: borsad | G19: Gujarat | H19: Deal | I19: 108000 | J19: 107017 | K19: =TRIM(Cleaned_CRM_Data!H19) -> Deal | L19: =IFERROR(VLOOKUP(K19, Status_Mapping!A:B, 2,), "Not Found") -> Converted | M19: 45824 | N19: =IF(M19="","",M19-B19) -> 7 | O19: =IF(OR(I19=108000,I19=130000),"Starter",IF(I19=177000,"Growth","Premium")) -> Starter | P19: =TEXT(B19, "mmmm") -> June | Q19: ="Q"&ROUNDUP(MONTH(B19)/3,0) -> Q2 | R19: =IFERROR(VLOOKUP(TRIM(CLEAN(G19)),Sheet14!$A$2:$B$19,2,FALSE),"Not Mapped") -> West
A20: ="EOS"&TEXT(ROW()-1,"0000") -> EOS0019 | B20: 45817 | C20: FB | D20: =TRIM(CLEAN(SUBSTITUTE(C20,CHAR(160),""))) -> FB | E20: Mushtaq kapadia | F20: Surat | G20: Gujarat | H20: Rejected | I20: 177000 | J20: 107018 | K20: =TRIM(Cleaned_CRM_Data!H20) -> Rejected | L20: =IFERROR(VLOOKUP(K20, Status_Mapping!A:B, 2,), "Not Found") -> Rejected | N20: =IF(M20="","",M20-B20) | O20: =IF(OR(I20=108000,I20=130000),"Starter",IF(I20=177000,"Growth","Premium")) -> Growth | P20: =TEXT(B20, "mmmm") -> June | Q20: ="Q"&ROUNDUP(MONTH(B20)/3,0) -> Q2 | R20: =IFERROR(VLOOKUP(TRIM(CLEAN(G20)),Sheet14!$A$2:$B$19,2,FALSE),"Not Mapped") -> West
A21: ="EOS"&TEXT(ROW()-1,"0000") -> EOS0020 | B21: 45817 | C21: FB | D21: =TRIM(CLEAN(SUBSTITUTE(C21,CHAR(160),""))) -> FB | E21: Ravi Bhetariya | F21: Jamnagar | G21: Gujarat | H21: Rejected | I21: 108000 | J21: 107019 | K21: =TRIM(Cleaned_CRM_Data!H21) -> Rejected | L21: =IFERROR(VLOOKUP(K21, Status_Mapping!A:B, 2,), "Not Found") -> Rejected | N21: =IF(M21="","",M21-B21) | O21: =IF(OR(I21=108000,I21=130000),"Starter",IF(I21=177000,"Growth","Premium")) -> Starter | P21: =TEXT(B21, "mmmm") -> June | Q21: ="Q"&ROUNDUP(MONTH(B21)/3,0) -> Q2 | R21: =IFERROR(VLOOKUP(TRIM(CLEAN(G21)),Sheet14!$A$2:$B$19,2,FALSE),"Not Mapped") -> West
A22: ="EOS"&TEXT(ROW()-1,"0000") -> EOS0021 | B22: 45817 | C22: FB | D22: =TRIM(CLEAN(SUBSTITUTE(C22,CHAR(160),""))) -> FB | E22: Patel Meet | F22: Bavla | G22: Gujarat | H22: Rejected | I22: 108000 | J22: 107020 | K22: deal | L22: =IFERROR(VLOOKUP(K22, Status_Mapping!A:B, 2,), "Not Found") -> Converted | N22: =IF(M22="","",M22-B22) | O22: =IF(OR(I22=108000,I22=130000),"Starter",IF(I22=177000,"Growth","Premium")) -> Starter | P22: =TEXT(B22, "mmmm") -> June | Q22: ="Q"&ROUNDUP(MONTH(B22)/3,0) -> Q2 | R22: =IFERROR(VLOOKUP(TRIM(CLEAN(G22)),Sheet14!$A$2:$B$19,2,FALSE),"Not Mapped") -> West
A23: ="EOS"&TEXT(ROW()-1,"0000") -> EOS0022 | B23: 45817 | C23: FB | D23: =TRIM(CLEAN(SUBSTITUTE(C23,CHAR(160),""))) -> FB | E23: Jagrut Jadeja | F23: Bantwa | G23: Gujarat | H23: Rejected | I23: 108000 | J23: 107021 | K23: =TRIM(Cleaned_CRM_Data!H23) -> Rejected | L23: =IFERROR(VLOOKUP(K23, Status_Mapping!A:B, 2,), "Not Found") -> Rejected | N23: =IF(M23="","",M23-B23) | O23: =IF(OR(I23=108000,I23=130000),"Starter",IF(I23=177000,"Growth","Premium")) -> Starter | P23: =TEXT(B23, "mmmm") -> June | Q23: ="Q"&ROUNDUP(MONTH(B23)/3,0) -> Q2 | R23: =IFERROR(VLOOKUP(TRIM(CLEAN(G23)),Sheet14!$A$2:$B$19,2,FALSE),"Not Mapped") -> West
A24: ="EOS"&TEXT(ROW()-1,"0000") -> EOS0023 | B24: 45817 | C24: FB | D24: =TRIM(CLEAN(SUBSTITUTE(C24,CHAR(160),""))) -> FB | E24: Gulamabbas Meghani | F24: Bhavnagar | G24: Gujarat | H24: Rejected | I24: 130000 | J24: 107022 | K24: =TRIM(Cleaned_CRM_Data!H24) -> Rejected | L24: =IFERROR(VLOOKUP(K24, Status_Mapping!A:B, 2,), "Not Found") -> Rejected | N24: =IF(M24="","",M24-B24) | O24: =IF(OR(I24=108000,I24=130000),"Starter",IF(I24=177000,"Growth","Premium")) -> Starter | P24: =TEXT(B24, "mmmm") -> June | Q24: ="Q"&ROUNDUP(MONTH(B24)/3,0) -> Q2 | R24: =IFERROR(VLOOKUP(TRIM(CLEAN(G24)),Sheet14!$A$2:$B$19,2,FALSE),"Not Mapped") -> West
A25: ="EOS"&TEXT(ROW()-1,"0000") -> EOS0024 | B25: 45817 | C25: FB | D25: =TRIM(CLEAN(SUBSTITUTE(C25,CHAR(160),""))) -> FB | E25: 𝕯ɪʟɪᴘ Ⱥᴄʜᴀʀʏᴀ | F25: Tharad | G25: Gujarat | H25: Rejected | I25: 108000 | J25: 107023 | K25: =TRIM(Cleaned_CRM_Data!H25) -> Rejected | L25: =IFERROR(VLOOKUP(K25, Status_Mapping!A:B, 2,), "Not Found") -> Rejected | N25: =IF(M25="","",M25-B25) | O25: =IF(OR(I25=108000,I25=130000),"Starter",IF(I25=177000,"Growth","Premium")) -> Starter | P25: =TEXT(B25, "mmmm") -> June | Q25: ="Q"&ROUNDUP(MONTH(B25)/3,0) -> Q2 | R25: =IFERROR(VLOOKUP(TRIM(CLEAN(G25)),Sheet14!$A$2:$B$19,2,FALSE),"Not Mapped") -> West
A26: ="EOS"&TEXT(ROW()-1,"0000") -> EOS0025 | B26: 45817 | C26: FB | D26: =TRIM(CLEAN(SUBSTITUTE(C26,CHAR(160),""))) -> FB | E26: mayur_ahir_3543 | F26: Rajkot | G26: Gujarat | H26: Rejected | I26: 108000 | J26: 107024 | K26: =TRIM(Cleaned_CRM_Data!H26) -> Rejected | L26: =IFERROR(VLOOKUP(K26, Status_Mapping!A:B, 2,), "Not Found") -> Rejected | N26: =IF(M26="","",M26-B26) | O26: =IF(OR(I26=108000,I26=130000),"Starter",IF(I26=177000,"Growth","Premium")) -> Starter | P26: =TEXT(B26, "mmmm") -> June | Q26: ="Q"&ROUNDUP(MONTH(B26)/3,0) -> Q2 | R26: =IFERROR(VLOOKUP(TRIM(CLEAN(G26)),Sheet14!$A$2:$B$19,2,FALSE),"Not Mapped") -> West
A27: ="EOS"&TEXT(ROW()-1,"0000") -> EOS0026 | B27: 45817 | C27: FB | D27: =TRIM(CLEAN(SUBSTITUTE(C27,CHAR(160),""))) -> FB | E27: Patel Jay | F27: Khambhat | G27: Gujarat | H27: Rejected | I27: 108000 | J27: 107025 | K27: =TRIM(Cleaned_CRM_Data!H27) -> Rejected | L27: =IFERROR(VLOOKUP(K27, Status_Mapping!A:B, 2,), "Not Found") -> Rejected | N27: =IF(M27="","",M27-B27) | O27: =IF(OR(I27=108000,I27=130000),"Starter",IF(I27=177000,"Growth","Premium")) -> Starter | P27: =TEXT(B27, "mmmm") -> June | Q27: ="Q"&ROUNDUP(MONTH(B27)/3,0) -> Q2 | R27: =IFERROR(VLOOKUP(TRIM(CLEAN(G27)),Sheet14!$A$2:$B$19,2,FALSE),"Not Mapped") -> West
A28: ="EOS"&TEXT(ROW()-1,"0000") -> EOS0027 | B28: 45817 | C28: FB | D28: =TRIM(CLEAN(SUBSTITUTE(C28,CHAR(160),""))) -> FB | E28: Keval Makwana | F28: Rajkot | G28: Gujarat | H28: Rejected | I28: 108000 | J28: 107026 | K28: =TRIM(Cleaned_CRM_Data!H28) -> Rejected | L28: =IFERROR(VLOOKUP(K28, Status_Mapping!A:B, 2,), "Not Found") -> Rejected | N28: =IF(M28="","",M28-B28) | O28: =IF(OR(I28=108000,I28=130000),"Starter",IF(I28=177000,"Growth","Premium")) -> Starter | P28: =TEXT(B28, "mmmm") -> June | Q28: ="Q"&ROUNDUP(MONTH(B28)/3,0) -> Q2 | R28: =IFERROR(VLOOKUP(TRIM(CLEAN(G28)),Sheet14!$A$2:$B$19,2,FALSE),"Not Mapped") -> West
A29: ="EOS"&TEXT(ROW()-1,"0000") -> EOS0028 | B29: 45817 | C29: FB | D29: =TRIM(CLEAN(SUBSTITUTE(C29,CHAR(160),""))) -> FB | E29: Mehul | F29: Mota chiloda | G29: Gujarat | H29: Rejected | I29: 130000 | J29: 107027 | K29: =TRIM(Cleaned_CRM_Data!H29) -> Rejected | L29: =IFERROR(VLOOKUP(K29, Status_Mapping!A:B, 2,), "Not Found") -> Rejected | N29: =IF(M29="","",M29-B29) | O29: =IF(OR(I29=108000,I29=130000),"Starter",IF(I29=177000,"Growth","Premium")) -> Starter | P29: =TEXT(B29, "mmmm") -> June | Q29: ="Q"&ROUNDUP(MONTH(B29)/3,0) -> Q2 | R29: =IFERROR(VLOOKUP(TRIM(CLEAN(G29)),Sheet14!$A$2:$B$19,2,FALSE),"Not Mapped") -> West
A30: ="EOS"&TEXT(ROW()-1,"0000") -> EOS0029 | B30: 45817 | C30: FB | D30: =TRIM(CLEAN(SUBSTITUTE(C30,CHAR(160),""))) -> FB | E30: Shànú Pàrmàr | F30: Mehsana | G30: Gujarat | H30: Rejected | I30: 130000 | J30: 107028 | K30: =TRIM(Cleaned_CRM_Data!H30) -> Rejected | L30: =IFERROR(VLOOKUP(K30, Status_Mapping!A:B, 2,), "Not Found") -> Rejected | N30: =IF(M30="","",M30-B30) | O30: =IF(OR(I30=108000,I30=130000),"Starter",IF(I30=177000,"Growth","Premium")) -> Starter | P30: =TEXT(B30, "mmmm") -> June | Q30: ="Q"&ROUNDUP(MONTH(B30)/3,0) -> Q2 | R30: =IFERROR(VLOOKUP(TRIM(CLEAN(G30)),Sheet14!$A$2:$B$19,2,FALSE),"Not Mapped") -> West
A31: ="EOS"&TEXT(ROW()-1,"0000") -> EOS0030 | B31: 45817 | C31: FB | D31: =TRIM(CLEAN(SUBSTITUTE(C31,CHAR(160),""))) -> FB | E31: ak_dhapa_2287 | F31: Jamnagar | G31: Gujarat | H31: Rejected | I31: 108000 | J31: 107029 | K31: =TRIM(Cleaned_CRM_Data!H31) -> Rejected | L31: =IFERROR(VLOOKUP(K31, Status_Mapping!A:B, 2,), "Not Found") -> Rejected | N31: =IF(M31="","",M31-B31) | O31: =IF(OR(I31=108000,I31=130000),"Starter",IF(I31=177000,"Growth","Premium")) -> Starter | P31: =TEXT(B31, "mmmm") -> June | Q31: ="Q"&ROUNDUP(MONTH(B31)/3,0) -> Q2 | R31: =IFERROR(VLOOKUP(TRIM(CLEAN(G31)),Sheet14!$A$2:$B$19,2,FALSE),"Not Mapped") -> West
A32: ="EOS"&TEXT(ROW()-1,"0000") -> EOS0031 | B32: 45817 | C32: FB | D32: =TRIM(CLEAN(SUBSTITUTE(C32,CHAR(160),""))) -> FB | E32: Rakesh Yogi | F32: Patan | G32: Gujarat | H32: Rejected | I32: 108000 | J32: 107030 | K32: =TRIM(Cleaned_CRM_Data!H32) -> Rejected | L32: =IFERROR(VLOOKUP(K32, Status_Mapping!A:B, 2,), "Not Found") -> Rejected | N32: =IF(M32="","",M32-B32) | O32: =IF(OR(I32=108000,I32=130000),"Starter",IF(I32=177000,"Growth","Premium")) -> Starter | P32: =TEXT(B32, "mmmm") -> June | Q32: ="Q"&ROUNDUP(MONTH(B32)/3,0) -> Q2 | R32: =IFERROR(VLOOKUP(TRIM(CLEAN(G32)),Sheet14!$A$2:$B$19,2,FALSE),"Not Mapped") -> West
A33: ="EOS"&TEXT(ROW()-1,"0000") -> EOS0032 | B33: 45817 | C33: FB | D33: =TRIM(CLEAN(SUBSTITUTE(C33,CHAR(160),""))) -> FB | E33: Vijay Patel | F33: Nadiad | G33: Gujarat | H33: Rejected | I33: 108000 | J33: 107031 | K33: =TRIM(Cleaned_CRM_Data!H33) -> Rejected | L33: =IFERROR(VLOOKUP(K33, Status_Mapping!A:B, 2,), "Not Found") -> Rejected | N33: =IF(M33="","",M33-B33) | O33: =IF(OR(I33=108000,I33=130000),"Starter",IF(I33=177000,"Growth","Premium")) -> Starter | P33: =TEXT(B33, "mmmm") -> June | Q33: ="Q"&ROUNDUP(MONTH(B33)/3,0) -> Q2 | R33: =IFERROR(VLOOKUP(TRIM(CLEAN(G33)),Sheet14!$A$2:$B$19,2,FALSE),"Not Mapped") -> West
A34: ="EOS"&TEXT(ROW()-1,"0000") -> EOS0033 | B34: 45817 | C34: FB | D34: =TRIM(CLEAN(SUBSTITUTE(C34,CHAR(160),""))) -> FB | E34: $oyeb | F34: Halol | G34: Gujarat | H34: Rejected | I34: 177000 | J34: 107032 | K34: =TRIM(Cleaned_CRM_Data!H34) -> Rejected | L34: =IFERROR(VLOOKUP(K34, Status_Mapping!A:B, 2,), "Not Found") -> Rejected | N34: =IF(M34="","",M34-B34) | O34: =IF(OR(I34=108000,I34=130000),"Starter",IF(I34=177000,"Growth","Premium")) -> Growth | P34: =TEXT(B34, "mmmm") -> June | Q34: ="Q"&ROUNDUP(MONTH(B34)/3,0) -> Q2 | R34: =IFERROR(VLOOKUP(TRIM(CLEAN(G34)),Sheet14!$A$2:$B$19,2,FALSE),"Not Mapped") -> West
... A46: ="EOS"&TEXT(ROW()-1,"0000") -> EOS0045 | B46: 45819 | C46: FB | D46: =TRIM(CLEAN(SUBSTITUTE(C46,CHAR(160),""))) -> FB | E46: Hitesh Parmar | F46: Ahmedabad | G46: Gujarat | H46: Rejected | I46: 130000 | J46: 107044 | K46: =TRIM(Cleaned_CRM_Data!H46) -> Rejected | L46: =IFERROR(VLOOKUP(K46, Status_Mapping!A:B, 2,), "Not Found") -> Rejected | N46: =IF(M46="","",M46-B46) | O46: =IF(OR(I46=108000,I46=130000),"Starter",IF(I46=177000,"Growth","Premium")) -> Starter | P46: =TEXT(B46, "mmmm") -> June | Q46: ="Q"&ROUNDUP(MONTH(B46)/3,0) -> Q2 | R46: =IFERROR(VLOOKUP(TRIM(CLEAN(G46)),Sheet14!$A$2:$B$19,2,FALSE),"Not Mapped") -> West
A47: ="EOS"&TEXT(ROW()-1,"0000") -> EOS0046 | B47: 45819 | C47: FB | D47: =TRIM(CLEAN(SUBSTITUTE(C47,CHAR(160),""))) -> FB | E47: 0 | F47: Kheralu | G47: Gujarat | H47: Rejected | I47: 108000 | J47: 107045 | K47: =TRIM(Cleaned_CRM_Data!H47) -> Rejected | L47: =IFERROR(VLOOKUP(K47, Status_Mapping!A:B, 2,), "Not Found") -> Rejected | N47: =IF(M47="","",M47-B47) | O47: =IF(OR(I47=108000,I47=130000),"Starter",IF(I47=177000,"Growth","Premium")) -> Starter | P47: =TEXT(B47, "mmmm") -> June | Q47: ="Q"&ROUNDUP(MONTH(B47)/3,0) -> Q2 | R47: =IFERROR(VLOOKUP(TRIM(CLEAN(G47)),Sheet14!$A$2:$B$19,2,FALSE),"Not Mapped") -> West
A48: ="EOS"&TEXT(ROW()-1,"0000") -> EOS0047 | B48: 45819 | C48: FB | D48: =TRIM(CLEAN(SUBSTITUTE(C48,CHAR(160),""))) -> FB | E48: karmrajsinh vadher | F48: Jamnagar | G48: Gujarat | H48: Rejected | I48: 108000 | J48: 107046 | K48: =TRIM(Cleaned_CRM_Data!H48) -> Rejected | L48: =IFERROR(VLOOKUP(K48, Status_Mapping!A:B, 2,), "Not Found") -> Rejected | N48: =IF(M48="","",M48-B48) | O48: =IF(OR(I48=108000,I48=130000),"Starter",IF(I48=177000,"Growth","Premium")) -> Starter | P48: =TEXT(B48, "mmmm") -> June | Q48: ="Q"&ROUNDUP(MONTH(B48)/3,0) -> Q2 | R48: =IFERROR(VLOOKUP(TRIM(CLEAN(G48)),Sheet14!$A$2:$B$19,2,FALSE),"Not Mapped") -> West
A49: ="EOS"&TEXT(ROW()-1,"0000") -> EOS0048 | B49: 45819 | C49: FB | D49: =TRIM(CLEAN(SUBSTITUTE(C49,CHAR(160),""))) -> FB | E49: Vivek Diyora | F49: Surat | G49: Gujarat | H49: Rejected | I49: 130000 | J49: 107047 | K49: =TRIM(Cleaned_CRM_Data!H49) -> Rejected | L49: =IFERROR(VLOOKUP(K49, Status_Mapping!A:B, 2,), "Not Found") -> Rejected | N49: =IF(M49="","",M49-B49) | O49: =IF(OR(I49=108000,I49=130000),"Starter",IF(I49=177000,"Growth","Premium")) -> Starter | P49: =TEXT(B49, "mmmm") -> June | Q49: ="Q"&ROUNDUP(MONTH(B49)/3,0) -> Q2 | R49: =IFERROR(VLOOKUP(TRIM(CLEAN(G49)),Sheet14!$A$2:$B$19,2,FALSE),"Not Mapped") -> West
A50: ="EOS"&TEXT(ROW()-1,"0000") -> EOS0049 | B50: 45819 | C50: FB | D50: =TRIM(CLEAN(SUBSTITUTE(C50,CHAR(160),""))) -> FB | E50: Rajendrasinh Parmar | F50: Gandhinagar | G50: Gujarat | H50: Rejected | I50: 108000 | J50: 107048 | K50: =TRIM(Cleaned_CRM_Data!H50) -> Rejected | L50: =IFERROR(VLOOKUP(K50, Status_Mapping!A:B, 2,), "Not Found") -> Rejected | N50: =IF(M50="","",M50-B50) | O50: =IF(OR(I50=108000,I50=130000),"Starter",IF(I50=177000,"Growth","Premium")) -> Starter | P50: =TEXT(B50, "mmmm") -> June | Q50: ="Q"&ROUNDUP(MONTH(B50)/3,0) -> Q2 | R50: =IFERROR(VLOOKUP(TRIM(CLEAN(G50)),Sheet14!$A$2:$B$19,2,FALSE),"Not Mapped") -> West
A51: ="EOS"&TEXT(ROW()-1,"0000") -> EOS0050 | B51: 45819 | C51: FB | D51: =TRIM(CLEAN(SUBSTITUTE(C51,CHAR(160),""))) -> FB | E51: Gunjan // gp... | F51: Patan | G51: Gujarat | H51: Rejected | I51: 308000 | J51: 107049 | K51: =TRIM(Cleaned_CRM_Data!H51) -> Rejected | L51: =IFERROR(VLOOKUP(K51, Status_Mapping!A:B, 2,), "Not Found") -> Rejected | N51: =IF(M51="","",M51-B51) | O51: =IF(OR(I51=108000,I51=130000),"Starter",IF(I51=177000,"Growth","Premium")) -> Premium | P51: =TEXT(B51, "mmmm") -> June | Q51: ="Q"&ROUNDUP(MONTH(B51)/3,0) -> Q2 | R51: =IFERROR(VLOOKUP(TRIM(CLEAN(G51)),Sheet14!$A$2:$B$19,2,FALSE),"Not Mapped") -> West
A52: ="EOS"&TEXT(ROW()-1,"0000") -> EOS0051 | B52: 45819 | C52: FB | D52: =TRIM(CLEAN(SUBSTITUTE(C52,CHAR(160),""))) -> FB | E52: 𝐏 𝐀 𝐑 𝐓 𝐇 | F52: Surendranagar | G52: Gujarat | H52: Rejected | I52: 130000 | J52: 107050 | K52: =TRIM(Cleaned_CRM_Data!H52) -> Rejected | L52: =IFERROR(VLOOKUP(K52, Status_Mapping!A:B, 2,), "Not Found") -> Rejected | N52: =IF(M52="","",M52-B52) | O52: =IF(OR(I52=108000,I52=130000),"Starter",IF(I52=177000,"Growth","Premium")) -> Starter | P52: =TEXT(B52, "mmmm") -> June | Q52: ="Q"&ROUNDUP(MONTH(B52)/3,0) -> Q2 | R52: =IFERROR(VLOOKUP(TRIM(CLEAN(G52)),Sheet14!$A$2:$B$19,2,FALSE),"Not Mapped") -> West
A53: ="EOS"&TEXT(ROW()-1,"0000") -> EOS0052 | B53: 45819 | C53: FB | D53: =TRIM(CLEAN(SUBSTITUTE(C53,CHAR(160),""))) -> FB | E53: D.m. Ahir | F53: Khambhalia | G53: Gujarat | H53: Rejected | I53: 177000 | J53: 107051 | K53: =TRIM(Cleaned_CRM_Data!H53) -> Rejected | L53: =IFERROR(VLOOKUP(K53, Status_Mapping!A:B, 2,), "Not Found") -> Rejected | N53: =IF(M53="","",M53-B53) | O53: =IF(OR(I53=108000,I53=130000),"Starter",IF(I53=177000,"Growth","Premium")) -> Growth | P53: =TEXT(B53, "mmmm") -> June | Q53: ="Q"&ROUNDUP(MONTH(B53)/3,0) -> Q2 | R53: =IFERROR(VLOOKUP(TRIM(CLEAN(G53)),Sheet14!$A$2:$B$19,2,FALSE),"Not Mapped") -> West
A54: ="EOS"&TEXT(ROW()-1,"0000") -> EOS0053 | B54: 45819 | C54: FB | D54: =TRIM(CLEAN(SUBSTITUTE(C54,CHAR(160),""))) -> FB | E54: Sandip Solanki | F54: Borsad | G54: Gujarat | H54: Rejected | I54: 108000 | J54: 107052 | K54: =TRIM(Cleaned_CRM_Data!H54) -> Rejected | L54: =IFERROR(VLOOKUP(K54, Status_Mapping!A:B, 2,), "Not Found") -> Rejected | N54: =IF(M54="","",M54-B54) | O54: =IF(OR(I54=108000,I54=130000),"Starter",IF(I54=177000,"Growth","Premium")) -> Starter | P54: =TEXT(B54, "mmmm") -> June | Q54: ="Q"&ROUNDUP(MONTH(B54)/3,0) -> Q2 | R54: =IFERROR(VLOOKUP(TRIM(CLEAN(G54)),Sheet14!$A$2:$B$19,2,FALSE),"Not Mapped") -> West
A55: ="EOS"&TEXT(ROW()-1,"0000") -> EOS0054 | B55: 45819 | C55: FB | D55: =TRIM(CLEAN(SUBSTITUTE(C55,CHAR(160),""))) -> FB | E55: Ammar Vahora | F55: Anand | G55: Gujarat | H55: Rejected | I55: 108000 | J55: 107053 | K55: =TRIM(Cleaned_CRM_Data!H55) -> Rejected | L55: =IFERROR(VLOOKUP(K55, Status_Mapping!A:B, 2,), "Not Found") -> Rejected | N55: =IF(M55="","",M55-B55) | O55: =IF(OR(I55=108000,I55=130000),"Starter",IF(I55=177000,"Growth","Premium")) -> Starter | P55: =TEXT(B55, "mmmm") -> June | Q55: ="Q"&ROUNDUP(MONTH(B55)/3,0) -> Q2 | R55: =IFERROR(VLOOKUP(TRIM(CLEAN(G55)),Sheet14!$A$2:$B$19,2,FALSE),"Not Mapped") -> West
...

Sheet KPI_Databse
A1: Total Leads | B1: ='Month Wise analysis'!B17 -> 1778
A2: Converted Leads | B2: =Sheet4!B4 -> 45
A3: Conversion rate | B3: =B2/B1 -> 0.025309336
A4: Revenue generated | B4: =Sheet4!C4 -> 6198000
A5: Pipeline value | B5: =Sheet4!C5 -> 69576000
A6: Lost opportunity | B6: =Sheet4!C7 -> 119264000
A7: Avg Closure Days | B7: ='Sales Cycle Analysis'!B7 -> 13

Sheet Sales Cycle Analysis
A1: Standard Status | B1: Converted
A3: Pacakge Category | B3: Average of Days To Closure
A4: Growth | B4: 6.5
A5: Premium | B5: 11
A6: Starter | B6: 14.307692
A7: Grand Total | B7: 13
A11: Standard Status | B11: Converted
A13: Zone | B13: Average of Days To Closure
A14: Central | B14: 7
A15: East | B15: 9
A16: North | B16: 10
A17: West | B17: 13.928571
A18: Grand Total | B18: 13
A24: Standard Status | B24: Converted
A26: Zone | B26: Total Revenue Generated
A27: Central | B27: 354000
A28: East | B28: 108000
A29: North | B29: 390000
A30: West | B30: 5346000
A31: Grand Total | B31: 6198000

Sheet Sheet4
A3: Standard Status | B3: Count of Lead ID | C3: Sum of Franchise Package Amount
A4: Converted | B4: 45 | C4: 6198000
A5: Follow Up | B5: 541 | C5: 69576000
A6: Not Found | B6: 268 | C6: 34561000
A7: Rejected | B7: 924 | C7: 119264000
A8: (blank)
A9: Grand Total | B9: 1778 | C9: 229599000

Sheet Month Wise analysis
E1: Standard Status | F1: Converted
A3: Lead Month | B3: Total Leads | E3: Lead Month | F3: Converted Leads
A4: January | B4: 150 | E4: March | F4: 3
A5: February | B5: 123 | E5: April | F5: 3
A6: March | B6: 60 | E6: May | F6: 1
A7: April | B7: 135 | E7: June | F7: 13
A8: May | B8: 134 | E8: July | F8: 8
A9: June | B9: 199 | E9: August | F9: 3
A10: July | B10: 284 | E10: September | F10: 4
A11: August | B11: 194 | E11: October | F11: 9
A12: September | B12: 177 | E12: November | F12: 1
A13: October | B13: 116 | E13: Grand Total | F13: 45
A14: November | B14: 73 | G14: Monthly Conversion Rate
A15: December | B15: 133 | E15: January | F15: 0 | G15: 0
A16: (blank) | E16: February | F16: 0 | G16: 0
A17: Grand Total | B17: 1778 | E17: March | F17: 3 | G17: =F17/B6 -> 0.05
E18: April | F18: 3 | G18: =F18/B7 -> 0.022222222
E19: May | F19: 1 | G19: =F19/B8 -> 0.0074626866
E20: June | F20: 12 | G20: =F20/B9 -> 0.060301508
E21: July | F21: 8 | G21: =F21/B10 -> 0.028169014
E22: August | F22: 3 | G22: =F22/B11 -> 0.015463918
E23: September | F23: 2 | G23: =F23/B12 -> 0.011299435
E24: October | F24: 0 | G24: 0
E25: November | F25: 1 | G25: =F25/B14 -> 0.01369863
E26: December | F26: 0 | G26: 0

Sheet Monthly closed deals
A1: Standard Status | B1: Converted
A3: Lead Month | B3: Count of Lead ID
A4: March | B4: 3
A5: April | B5: 3
A6: May | B6: 1
A7: June | B7: 13
A8: July | B8: 8
A9: August | B9: 3
A10: September | B10: 4
A11: October | B11: 9
A12: November | B12: 1
A13: Grand Total | B13: 45

Sheet Total Pipeline Value
A3: Standard Status | B3: Sum of Franchise Package Amount
A4: Converted | B4: 6198000
A5: Follow Up | B5: 69576000
A6: Not Found | B6: 34561000
A7: Rejected | B7: 119264000
A8: (blank)
A9: Grand Total | B9: 229599000

Sheet Franchise performance
A1: Standard Status | B1: Converted
A3: Pacakge Category | B3: Sum of Franchise Package Amount
A4: Growth | B4: 708000
A5: Premium | B5: 816000
A6: Starter | B6: 4674000
A7: Grand Total | B7: 6198000
A11: Standard Status | B11: Converted
A13: Pacakge Category | B13: Total Leads | C13: Sum of Franchise Package Amount | D13: Conversion rate
A14: Growth | B14: 4 | C14: 708000 | D14: =B14/B4 -> 5.6497175e-06
A15: Premium | B15: 2 | C15: 816000 | D15: =B15/B5 -> 2.4509804e-06
A16: Starter | B16: 39 | C16: 4674000 | D16: =B16/B6 -> 8.3440308e-06
A17: Grand Total | B17: 45 | C17: 6198000

Sheet Zone Wise Analysis
A1: Standard Status | B1: (All)
A3: Zone | B3: Lead | C3: Count of Franchise Package Amount
A4: Central | B4: 30 | C4: 30
A5: East | B5: 49 | C5: 49
A6: North | B6: 112 | C6: 112
A7: Not Mapped | B7: 18 | C7: 18
A8: West | B8: 1569 | C8: 1569
A9: (blank)
A10: Grand Total | B10: 1778 | C10: 1778
A11: Standard Status | B11: Converted
A13: Zone | B13: Lead | C13: Potential revenue | D13: Zone Conversion Share | E13: Zone Conversion rate
A14: Central | B14: 2 | C14: 354000 | D14: =B14/B18 -> 0.044444444 | E14: =B14/B4 -> 0.066666667
A15: East | B15: 1 | C15: 108000 | D15: =B15/B18 -> 0.022222222 | E15: =B15/B5 -> 0.020408163
A16: North | B16: 3 | C16: 390000 | D16: =B16/B18 -> 0.066666667 | E16: =B16/B6 -> 0.026785714
A17: West | B17: 39 | C17: 5346000 | D17: =B17/B18 -> 0.86666667 | E17: =B17/B8 -> 0.024856597
A18: Grand Total | B18: 45 | C18: 6198000
A23: 2
A24: 1
A25: 3
A26: 27

Sheet Sheet5
C2: Total Leads | E2: Conversion Rate
C3: =COUNTA(Cleaned_CRM_Data!A2:A1779) -> 1778 | E3: =C6/C3 -> 0.025309336
C5: Converted Leads | E5: Total Converted revenue
C6: =COUNTIF(Cleaned_CRM_Data!L:L,"Converted") -> 45 | E6: =SUMIF(Cleaned_CRM_Data!L:L,"Converted",Cleaned_CRM_Data!I:I) -> 6198000
E8: Pipeline Value
E9: =SUMIF(Cleaned_CRM_Data!L:L, "Follow up",Cleaned_CRM_Data!I:I) -> 69576000
E11: Lost Opportunity Value
C12: ` | E12: =SUMIF(Cleaned_CRM_Data!L:L, "Rejected", Cleaned_CRM_Data!I:I) -> 119264000

Sheet Status_Mapping
A1: Raw_Status | B1: Standard_Status
A2: Deal | B2: Converted
A3: Deal Done | B3: Converted
A4: Follow up | B4: Follow Up
A5: Ringing | B5: Follow Up
A6: Rejected | B6: Rejected
E10: =F754 -> 0
